Workbook

Sheet Datainsamling
A1: FÖRETAG | B1: Organisationsnummer | C1: ISIN | D1: LAND | E1: BRANSCH | F1: WACC23 | G1: WACC22 | H1: WACC21 | I1: WACC20 | J1: WACC19 | K1: INF23 | L1: INF22 | M1: INF21 | N1: INF20 | O1: INF19 | P1: SR19 | Q1: SR20 | R1: SR21 | S1: SR22 | T1: SR23 | U1: GWN23 (Tkr) | V1: GWN22 (Tkr) | W1: GWN21 (Tkr) | X1: GWN20 (Tkr) | Y1: GWN19 (Tkr) | Z1: Anställda_n_23 | AA1: Anställda_n_22 | AB1: Anställda_n_21 | AC1: Anställda_n_20 | AD1: Anställda_n_19 | AE1: EBITDA_tkr_23 | AF1: EBITDA_tkr_22 | AG1: EBITDA_tkr_21 | AH1: EBITDA_tkr_20 | AI1: EBITDA_tkr_19 | AJ1: SGR_%_23 | AK1: SGR_%_22 | AL1: SGR_%_21 | AM1: SGR_%_20 | AN1: SGR_%_19 | AO1: VM_%_23 | AP1: VM_%_22 | AQ1: VM_%_21 | AR1: VM_%_20 | AS1: VM_%_19 | AT1: SL23 | AU1: SL22 | AV1: SL21 | AW1: SL20 | AX1: SL19 | AY1: OMS_tkr_23 | AZ1: OMS_tkr_22 | BA1: OMS_tkr_21 | BB1: OMS_tkr_20 | BC1: OMS_tkr_19 | BD1: GW_tkr_23 | BE1: GW_tkr_22 | BF1: GW_tkr_21 | BG1: GW_tkr_20 | BH1: GW_tkr_19 | BI1: TT_tkr_2023 | BJ1: TT_tkr_2022 | BK1: TT_tkr_2021 | BL1: TT_tkr_2020 | BM1: TT_tkr_2019 | BN1: S:EK_tkr_23 | BO1: S:EK_tkr_22 | BP1: S:EK_tkr_21 | BQ1: S:EK_tkr_20 | BR1: S:EK_tkr_19
A2: AAK AB (publ) | B2: 5566692850 | C2: SE0011337708 | D2: SWE | E2: Företagstjänster | F2: 0.1 | G2: 0.09 | H2: 0.08 | I2: 0.08 | J2: 0.114 | K2: 0.085 | L2: 0.084 | M2: 0.022 | N2: 0.005 | O2: 0.018 | P2: -0.00255 | Q2: -0.00029762 | R2: 0 | S2: 0.0076779 | T2: 0.0346414 | U2: 0 | V2: 0 | W2: 0 | X2: 0 | Y2: 0 | Z2: 4128 | AA2: 3962 | AB2: 4013 | AC2: 551 | AD2: 3884 | AE2: 4993000 | AF2: 3337000 | AG2: 3047000 | AH2: 2922000 | AI2: 2829000 | AJ2: 0.74924895 | AK2: 2.3176506 | AL2: 1.8093206 | AM2: 1.5793977 | AN2: 1.7515023 | AO2: {=('1100'!G2) / 100} -> 0.0912 | AP2: {=('1100'!H2) / 100} -> 0.0517 | AQ2: {=('1100'!I2) / 100} -> 0.0595 | AR2: {=('1100'!J2) / 100} -> 0.0783 | AS2: {=('1100'!K2) / 100} -> 0.076 | AT2: {=('1100'!A2) / 100} -> 0.56 | AU2: {=('1100'!B2) / 100} -> 0.442 | AV2: {=('1100'!C2) / 100} -> 0.434 | AW2: {=('1100'!D2) / 100} -> 0.435 | AX2: {=('1100'!E2) / 100} -> 0.451 | AY2: 46201000 | AZ2: 50775000 | BA2: 35994000 | BB2: 28298000 | BC2: 28703000 | BD2: 2712000 | BE2: 2538000 | BF2: 2270000 | BG2: 2103000 | BH2: 2114000 | BI2: 30551000 | BJ2: 33990000 | BK2: 27166000 | BL2: 22278000 | BM2: 22919000 | BN2: 17117000 | BO2: 15036000 | BP2: 11783000 | BQ2: 9699000 | BR2: 10337000
A3: Addtech AB | B3: 5563029726 | C3: SE0014781795 | D3: SWE | E3: Företagstjänster | F3: 0.13 | G3: 0.13 | H3: 0.13 | I3: 0.11 | J3: 0.11 | K3: 0.085 | L3: 0.084 | M3: 0.022 | N3: 0.005 | O3: 0.018 | P3: -0.00255 | Q3: -0.00029762 | R3: 0 | S3: 0.0076779 | T3: 0.0346414 | U3: 0 | V3: 0 | W3: 0 | X3: 0 | Y3: 0 | Z3: 4109 | AA3: 3781 | AB3: 3317 | AC3: 3068 | AD3: 2913 | AE3: 3245000 | AF3: 2872000 | AG3: 2933000 | AH3: 1501 | AI3: 1579000 | AJ3: 1.4434515 | AK3: 1.4860724 | AL3: 0.91851347 | AM3: 2.4083944 | AN3: 1.7555415 | AO3: {=('1100'!G3) / 100} -> 0.1235 | AP3: {=('1100'!H3) / 100} -> 0.1165 | AQ3: {=('1100'!I3) / 100} -> 0.1072 | AR3: {=('1100'!J3) / 100} -> 0.0884 | AS3: {=('1100'!K3) / 100} -> 0.0994 | AT3: {=('1100'!A3) / 100} -> 0.359 | AU3: {=('1100'!B3) / 100} -> 0.339 | AV3: {=('1100'!C3) / 100} -> 0.316 | AW3: {=('1100'!D3) / 100} -> 0.328 | AX3: {=('1100'!E3) / 100} -> 0.355 | AY3: 20117000 | AZ3: 18834000 | BA3: 14138000 | BB3: 11416 | BC3: 11851000 | BD3: 4716000 | BE3: 3935000 | BF3: 3306000 | BG3: 2727000 | BH3: 1997000 | BI3: 16657000 | BJ3: 15271000 | BK3: 12427000 | BL3: 9806 | BM3: 8506000 | BN3: 5974000 | BO3: 5184000 | BP3: 3931000 | BQ3: 3219000 | BR3: 3018000
A4: AFRY AB | B4: 5561206474 | C4: SE0005999836 | D4: SWE | E4: Företagstjänster | F4: 0.125 | G4: 0.11 | H4: 0.09 | I4: 0.09 | J4: 0.095 | K4: 0.085 | L4: 0.084 | M4: 0.022 | N4: 0.005 | O4: 0.018 | P4: -0.00255 | Q4: -0.00029762 | R4: 0 | S4: 0.0076779 | T4: 0.0346414 | U4: 0 | V4: 0 | W4: 0 | X4: 0 | Y4: 0 | Z4: 18228 | AA4: 17340 | AB4: 15647 | AC4: 15271 | AD4: 14680 | AE4: 2559000 | AF4: 2146000 | AG4: 2221000 | AH4: 2126000 | AI4: 1933000 | AJ4: 2.3712388 | AK4: 3.0950606 | AL4: 3.0283656 | AM4: 3.3795861 | AN4: 4.128298 | AO4: {=('1100'!G4) / 100} -> 0.0856 | AP4: {=('1100'!H4) / 100} -> 0.0943 | AQ4: {=('1100'!I4) / 100} -> 0.0878 | AR4: {=('1100'!J4) / 100} -> 0.0922 | AS4: {=('1100'!K4) / 100} -> 0.0735 | AT4: {=('1100'!A4) / 100} -> 0.442 | AU4: {=('1100'!B4) / 100} -> 0.435 | AV4: {=('1100'!C4) / 100} -> 0.424 | AW4: {=('1100'!D4) / 100} -> 0.428 | AX4: {=('1100'!E4) / 100} -> 0.384 | AY4: 26986000 | AZ4: 23658000 | BA4: 20167000 | BB4: 19194000 | BC4: 19823000 | BD4: 14778000 | BE4: 14431000 | BF4: 12814000 | BG4: 11460000 | BH4: 11768000 | BI4: 28172000 | BJ4: 27996000 | BK4: 25913000 | BL4: 23610000 | BM4: 24375000 | BN4: 12453000 | BO4: 12176000 | BP4: 10992000 | BQ4: 10096000 | BR4: 9367000
A5: Aktiebolaget Electrolux | B5: 5560094178 | C5: SE0016589170 | D5: SWE | E5: Företagstjänster | F5: 0.148 | G5: 0.106 | H5: 0.095 | I5: 0.095 | J5: 0.083 | K5: 0.085 | L5: 0.084 | M5: 0.022 | N5: 0.005 | O5: 0.018 | P5: -0.00255 | Q5: -0.00029762 | R5: 0 | S5: 0.0076779 | T5: 0.0346414 | U5: 0 | V5: 0 | W5: 0 | X5: 0 | Y5: 0 | Z5: 45452 | AA5: 50769 | AB5: 51590 | AC5: 47543 | AD5: 48652 | AE5: 3289000 | AF5: 4178000 | AG5: 11290000 | AH5: 10365000 | AI5: 8293000 | AJ5: 9.819398 | AK5: 7.821685 | AL5: 1.1385297 | AM5: 1.539508 | AN5: 1.3420957 | AO5: {=('1100'!G5) / 100} -> -0.019 | AP5: {=('1100'!H5) / 100} -> -0.0007 | AQ5: {=('1100'!I5) / 100} -> 0.0545 | AR5: {=('1100'!J5) / 100} -> 0.0505 | AS5: {=('1100'!K5) / 100} -> 0.0274 | AT5: {=('1100'!A5) / 100} -> 0.094 | AU5: {=('1100'!B5) / 100} -> 0.129 | AV5: {=('1100'!C5) / 100} -> 0.173 | AW5: {=('1100'!D5) / 100} -> 0.188 | AX5: {=('1100'!E5) / 100} -> 0.211 | AY5: 134667000 | AZ5: 135711000 | BA5: 125631000 | BB5: 115960000 | BC5: 120038000 | BD5: 6579000 | BE5: 7081000 | BF5: 6690000 | BG5: 6369000 | BH5: 7071000 | BI5: 120053000 | BJ5: 127102000 | BK5: 107607000 | BL5: 99604000 | BM5: 106808000 | BN5: 11268000 | BO5: 16443000 | BP5: 18604000 | BQ5: 18702000 | BR5: 22566000
A6: Aktiebolaget SKF | B6: 5560073495 | C6: SE0000108201 | D6: SWE | E6: Företagstjänster | F6: 0.13 | G6: 0.106 | H6: 0.0945 | I6: 0.106 | J6: 0.1135 | K6: 0.085 | L6: 0.084 | M6: 0.022 | N6: 0.005 | O6: 0.018 | P6: -0.00255 | Q6: -0.00029762 | R6: 0 | S6: 0.0076779 | T6: 0.0346414 | U6: 0 | V6: 0 | W6: 0 | X6: 0 | Y6: 0 | Z6: 39672 | AA6: 40773 | AB6: 40861 | AC6: 38385 | AD6: 41559 | AE6: 15872000 | AF6: 11461000 | AG6: 14063000 | AH6: 10439000 | AI6: 12891000 | AJ6: 1.1326235 | AK6: 1.9741733 | AL6: 1.1764915 | AM6: 1.7272727 | AN6: 2.6066248 | AO6: {=('1100'!G6) / 100} -> 0.1126 | AP6: {=('1100'!H6) / 100} -> 0.0893 | AQ6: {=('1100'!I6) / 100} -> 0.1327 | AR6: {=('1100'!J6) / 100} -> 0.0954 | AS6: {=('1100'!K6) / 100} -> 0.1126 | AT6: {=('1100'!A6) / 100} -> 0.471 | AU6: {=('1100'!B6) / 100} -> 0.468 | AV6: {=('1100'!C6) / 100} -> 0.438 | AW6: {=('1100'!D6) / 100} -> 0.379 | AX6: {=('1100'!E6) / 100} -> 0.377 | AY6: 106637000 | AZ6: 98278000 | BA6: 82941000 | BB6: 75185000 | BC6: 86285000 | BD6: 11962000 | BE6: 12351000 | BF6: 10924000 | BG6: 10117000 | BH6: 11251000 | BI6: 111903000 | BJ6: 110923000 | BK6: 99628000 | BL6: 90557000 | BM6: 94108000 | BN6: 52743000 | BO6: 51927000 | BP6: 43645000 | BQ6: 34309000 | BR6: 35512000
A7: Aktiebolaget Volvo | B7: 5560125790 | C7: SE0000115420 | D7: SWE | E7: Tillverkning & industri | F7: 0.1 | G7: 0.1 | H7: 0.1 | I7: 0.1 | J7: 0.1 | K7: 0.085 | L7: 0.084 | M7: 0.022 | N7: 0.005 | O7: 0.018 | P7: -0.00255 | Q7: -0.00029762 | R7: 0 | S7: 0.0076779 | T7: 0.0346414 | U7: 0 | V7: 0 | W7: 0 | X7: 0 | Y7: 0 | Z7: 89282 | AA7: 86316 | AB7: 83958 | AC7: 89573 | AD7: 93731 | AE7: 88011000 | AF7: 66441000 | AG7: 61794000 | AH7: 48516000 | AI7: 52494000 | AJ7: 2.0993967 | AK7: 2.7711804 | AL7: 2.2819044 | AM7: 2.6092423 | AN7: 2.6274812 | AO7: {=('1100'!G7) / 100} -> 0.1257 | AP7: {=('1100'!H7) / 100} -> 0.0987 | AQ7: {=('1100'!I7) / 100} -> 0.1192 | AR7: {=('1100'!J7) / 100} -> 0.0821 | AS7: {=('1100'!K7) / 100} -> 0.1154 | AT7: {=('1100'!A7) / 100} -> 0.264 | AU7: {=('1100'!B7) / 100} -> 0.259 | AV7: {=('1100'!C7) / 100} -> 0.273 | AW7: {=('1100'!D7) / 100} -> 0.284 | AX7: {=('1100'!E7) / 100} -> 0.27 | AY7: 552764000 | AZ7: 473611000 | BA7: 372462000 | BB7: 340195000 | BC7: 434124000 | BD7: 24861000 | BE7: 25636000 | BF7: 23924000 | BG7: 22981000 | BH7: 24135000 | BI7: 674068000 | BJ7: 629064000 | BK7: 515856000 | BL7: 510821000 | BM7: 524837000 | BN7: 177791000 | BO7: 162717000 | BP7: 141045000 | BQ7: 145295000 | BR7: 141677000
A8: Alfa Laval AB | B8: 5565878054 | C8: SE0000695876 | D8: SWE | E8: Bank, finans & försäkring | F8: 0.0997 | G8: 0.0986 | H8: 0.0911 | I8: 0.0969 | J8: 0.0919 | K8: 0.085 | L8: 0.084 | M8: 0.022 | N8: 0.005 | O8: 0.018 | P8: -0.00255 | Q8: -0.00029762 | R8: 0 | S8: 0.0076779 | T8: 0.0346414 | U8: 0 | V8: 0 | W8: 0 | X8: =360*1000 -> 360000 | Y8: 0 | Z8: 20803 | AA8: 19002 | AB8: 17419 | AC8: 3593 | AD8: 3537 | AE8: 11780000 | AF8: 8911000 | AG8: 8113000 | AH8: 7569000 | AI8: 9251000 | AJ8: 1.2562818 | AK8: 2.3214005 | AL8: 1.715395 | AM8: 1.4197384 | AN8: 1.5083775 | AO8: {=('1100'!G8) / 100} -> 0.1528 | AP8: {=('1100'!H8) / 100} -> 0.1303 | AQ8: {=('1100'!I8) / 100} -> 0.1594 | AR8: {=('1100'!J8) / 100} -> 0.1405 | AS8: {=('1100'!K8) / 100} -> 0.1635 | AT8: {=('1100'!A8) / 100} -> 0.45 | AU8: {=('1100'!B8) / 100} -> 0.435 | AV8: {=('1100'!C8) / 100} -> 0.499 | AW8: {=('1100'!D8) / 100} -> 0.475 | AX8: {=('1100'!E8) / 100} -> 0.429 | AY8: 64582000 | AZ8: 52955000 | BA8: 41897000 | BB8: 42309000 | BC8: 47711000 | BD8: 25069000 | BE8: 26258000 | BF8: 22480000 | BG8: 19080000 | BH8: 21112000 | BI8: 82288000 | BJ8: 81249000 | BK8: 64361000 | BL8: 60860000 | BM8: 64396000 | BN8: 37033000 | BO8: 35382000 | BP8: 32096000 | BQ8: 28908000 | BR8: 27600000
A9: Alimak Group AB (publ) | B9: 5567141857 | C9: SE0007158910 | D9: SWE | E9: Företagstjänster | F9: 0.094 | G9: 0.093 | H9: =0.068 -> 0.068 | I9: =0.091 -> 0.091 | J9: =0.086 -> 0.086 | K9: 0.085 | L9: 0.084 | M9: 0.022 | N9: 0.005 | O9: 0.018 | P9: -0.00255 | Q9: -0.00029762 | R9: 0 | S9: 0.0076779 | T9: 0.0346414 | U9: 0 | V9: 0 | W9: 0 | X9: 0 | Y9: 0 | Z9: 2956 | AA9: 2134 | AB9: 2057 | AC9: 2049 | AD9: 2286 | AE9: 1374000 | AF9: 759000 | AG9: 614300 | AH9: 456400 | AI9: 762200 | AJ9: 3.4112082 | AK9: 8.2239789 | AL9: 1.3753866 | AM9: 2.6463628 | AN9: 1.8921543 | AO9: {=('1100'!G9) / 100} -> 0.2063 | AP9: {=('1100'!H9) / 100} -> 0.1494 | AQ9: {=('1100'!I9) / 100} -> 0.1293 | AR9: {=('1100'!J9) / 100} -> 0.0761 | AS9: {=('1100'!K9) / 100} -> 0.1356 | AT9: {=('1100'!A9) / 100} -> 0.508 | AU9: {=('1100'!B9) / 100} -> 0.306 | AV9: {=('1100'!C9) / 100} -> 0.651 | AW9: {=('1100'!D9) / 100} -> 0.628 | AX9: {=('1100'!E9) / 100} -> 0.574 | AY9: 7166000 | AZ9: 4512000 | BA9: 3744300 | BB9: 3744400 | BC9: 4587400 | BD9: 5882000 | BE9: 5950000 | BF9: 2362000 | BG9: 2260400 | BH9: 2366700 | BI9: 13683000 | BJ9: 14327000 | BK9: 5901700 | BL9: 5619400 | BM9: 6416900 | BN9: 6955000 | BO9: 4377000 | BP9: 3840400 | BQ9: 3527900 | BR9: 3684200
A10: Alligo AB | B10: 5590721352 | C10: SE0009922305 | D10: SWE | E10: Företagstjänster | F10: 0.08 | G10: 0.08 | H10: 0.11 | I10: 0.11 | J10: 0.114 | K10: 0.085 | L10: 0.084 | M10: 0.022 | N10: 0.005 | O10: 0.018 | P10: -0.00255 | Q10: -0.00029762 | R10: 0 | S10: 0.0076779 | T10: 0.0346414 | U10: 0 | V10: 0 | W10: 0 | X10: 0 | Y10: 0 | Z10: 2444 | AA10: 2335 | AB10: 2323 | AC10: 2564 | AD10: 1700 | AE10: 1281000 | AF10: 1155000 | AG10: 990000 | AH10: 792000 | AI10: 0 | AJ10: 2.3950039 | AK10: 2.408658 | AL10: 2.4717172 | AM10: 3.2790404 | AN10: - | AO10: {=('1100'!G10) / 100} -> 0.0815 | AP10: {=('1100'!H10) / 100} -> 0.0731 | AQ10: {=('1100'!I10) / 100} -> 0.0507 | AR10: {=('1100'!J10) / 100} -> 0.0491 | AS10: {=('1100'!K10) / 100} -> 0 | AT10: {=('1100'!A10) / 100} -> 0.411 | AU10: {=('1100'!B10) / 100} -> 0.407 | AV10: {=('1100'!C10) / 100} -> 0.395 | AW10: {=('1100'!D10) / 100} -> 0.389 | AX10: {=('1100'!E10) / 100} -> 0 | AY10: 9462000 | AZ10: 9333000 | BA10: 8508000 | BB10: 6861000 | BC10: 6139000 | BD10: 1640000 | BE10: 1561000 | BF10: 1461000 | BG10: 1603000 | BH10: 553000 | BI10: 8787000 | BJ10: 8364000 | BK10: 8679000 | BL10: 7812000 | BM10: 5940000 | BN10: 3613000 | BO10: 3408000 | BP10: 3429000 | BQ10: 3037000 | BR10: 2869000
A11: Ambea AB ( publ ) | B11: 5564684354 | C11: SE0009663826 | D11: SWE | E11: Juridik, ekonomi & konsulttjänster | F11: =0.135 -> 0.135 | G11: 0.109 | H11: =0.105 -> 0.105 | I11: =0.109 -> 0.109 | J11: =0.091 -> 0.091 | K11: 0.085 | L11: 0.084 | M11: 0.022 | N11: 0.005 | O11: 0.018 | P11: -0.00255 | Q11: -0.00029762 | R11: 0 | S11: 0.0076779 | T11: 0.0346414 | U11: 0 | V11: 0 | W11: 0 | X11: 0 | Y11: 0 | Z11: 14663 | AA11: 14437 | AB11: 14292 | AC11: 13794 | AD11: 13214 | AE11: 2278000 | AF11: 2044000 | AG11: 1650000 | AH11: 1613000 | AI11: 1370000 | AJ11: 4.0452151 | AK11: 4.8542074 | AL11: 4.7375758 | AM11: 3.7985121 | AN11: 3.8708029 | AO11: {=('1100'!G11) / 100} -> 0.0739 | AP11: {=('1100'!H11) / 100} -> 0.0667 | AQ11: {=('1100'!I11) / 100} -> 0.0522 | AR11: {=('1100'!J11) / 100} -> 0.0648 | AS11: {=('1100'!K11) / 100} -> 0.0486 | AT11: {=('1100'!A11) / 100} -> 0.275 | AU11: {=('1100'!B11) / 100} -> 0.262 | AV11: {=('1100'!C11) / 100} -> 0.272 | AW11: {=('1100'!D11) / 100} -> 0.294 | AX11: {=('1100'!E11) / 100} -> 0.292 | AY11: 13583000 | AZ11: 12959000 | BA11: 11673000 | BB11: 11205000 | BC11: 11139000 | BD11: 7006000 | BE11: 7095000 | BF11: 7285000 | BG11: 6508000 | BH11: 6532000 | BI11: 17893000 | BJ11: 17875000 | BK11: 16674000 | BL11: 14718000 | BM11: 13810000 | BN11: 4920000 | BO11: 4681000 | BP11: 4530000 | BQ11: 4325000 | BR11: 4036000
A12: AQ Group AB | B12: 5562818830 | C12: SE0022062196 | D12: SWE | E12: Företagstjänster | F12: 0.1 | G12: 0.1 | H12: 0.0886 | I12: 0.0883 | J12: 0.0833 | K12: 0.085 | L12: 0.084 | M12: 0.022 | N12: 0.005 | O12: 0.018 | P12: -0.00255 | Q12: -0.00029762 | R12: 0 | S12: 0.0076779 | T12: 0.0346414 | U12: 0 | V12: 0 | W12: 0 | X12: 0 | Y12: 0 | Z12: 7846 | AA12: 7222 | AB12: 6477 | AC12: 5891 | AD12: 6330 | AE12: 1080000 | AF12: 752000 | AG12: 680000 | AH12: 635234 | AI12: 560686 | AJ12: 0.67037037 | AK12: 1.2646277 | AL12: 1.3852941 | AM12: 1.4139435 | AN12: 1.8633763 | AO12: {=('1100'!G12) / 100} -> 0.09 | AP12: {=('1100'!H12) / 100} -> 0.0751 | AQ12: {=('1100'!I12) / 100} -> 0.0857 | AR12: {=('1100'!J12) / 100} -> 0.0866 | AS12: {=('1100'!K12) / 100} -> 0.0687 | AT12: {=('1100'!A12) / 100} -> 0.628 | AU12: {=('1100'!B12) / 100} -> 0.555 | AV12: {=('1100'!C12) / 100} -> 0.557 | AW12: {=('1100'!D12) / 100} -> 0.564 | AX12: {=('1100'!E12) / 100} -> 0.521 | AY12: 9072000 | AZ12: 7315000 | BA12: 5798000 | BB12: 4953995 | BC12: 5188672 | BD12: 393000 | BE12: 395000 | BF12: 366000 | BG12: 330244 | BH12: 353246 | BI12: 5960000 | BJ12: 5704000 | BK12: 4699000 | BL12: 3864463 | BM12: 3852305 | BN12: 3743000 | BO12: 3164000 | BP12: 2616000 | BQ12: 2181135 | BR12: 2007735
A13: ASSA ABLOY AB | B13: 5560593575 | C13: SE0007100581 | D13: SWE | E13: Företagstjänster | F13: =0.085 -> 0.085 | G13: 0.08 | H13: 0.08 | I13: 0.08 | J13: 0.08 | K13: 0.085 | L13: 0.084 | M13: 0.022 | N13: 0.005 | O13: 0.018 | P13: -0.00255 | Q13: -0.00029762 | R13: 0 | S13: 0.0076779 | T13: 0.0346414 | U13: 0 | V13: 0 | W13: 0 | X13: 0 | Y13: 0 | Z13: 56845 | AA13: 52462 | AB13: 50935 | AC13: 48471 | AD13: 48992 | AE13: 25873000 | AF13: 18532000 | AG13: 18022000 | AH13: 16234000 | AI13: 16794000 | AJ13: 2.1185792 | AK13: 1.5614073 | AL13: 1.4633226 | AM13: 1.7588395 | AN13: 1.8534596 | AO13: {=('1100'!G13) / 100} -> 0.1561 | AP13: {=('1100'!H13) / 100} -> 0.1541 | AQ13: {=('1100'!I13) / 100} -> 0.1502 | AR13: {=('1100'!J13) / 100} -> 0.1423 | AS13: {=('1100'!K13) / 100} -> 0.1559 | AT13: {=('1100'!A13) / 100} -> 0.467 | AU13: {=('1100'!B13) / 100} -> 0.556 | AV13: {=('1100'!C13) / 100} -> 0.535 | AW13: {=('1100'!D13) / 100} -> 0.501 | AX13: {=('1100'!E13) / 100} -> 0.501 | AY13: 144321000 | AZ13: 120819000 | BA13: 95026000 | BB13: 89321000 | BC13: 94227000 | BD13: 92873000 | BE13: 75873000 | BF13: 62502000 | BG13: 58344000 | BH13: 57662000 | BI13: 196351000 | BJ13: 154564000 | BK13: 129975000 | BL13: 117428000 | BM13: 118050000 | BN13: 91629000 | BO13: 86014000 | BP13: 69582000 | BQ13: 58870000 | BR13: 59143000
A14: Atlas Copco Aktiebolag | B14: 5560142720 | C14: SE0017486889 | D14: SWE | E14: Företagstjänster | F14: 0.08 | G14: 0.08 | H14: 0.08 | I14: 0.08 | J14: 0.08 | K14: 0.085 | L14: 0.084 | M14: 0.022 | N14: 0.005 | O14: 0.018 | P14: -0.00255 | Q14: -0.00029762 | R14: 0 | S14: 0.0076779 | T14: 0.0346414 | U14: 0 | V14: 0 | W14: 0 | X14: 0 | Y14: 0 | Z14: 51110 | AA14: 45781 | AB14: 41272 | AC14: 39606 | AD14: 37805 | AE14: 44782000 | AF14: 36500000 | AG14: 28894000 | AH14: 21122000 | AI14: 25531000 | AJ14: 0.78781653 | AK14: 0.80383562 | AL14: 0.84221638 | AM14: 1.3429599 | AN14: 0.97336571 | AO14: {=('1100'!G14) / 100} -> 0.2174 | AP14: {=('1100'!H14) / 100} -> 0.2162 | AQ14: {=('1100'!I14) / 100} -> 0.2146 | AR14: {=('1100'!J14) / 100} -> 0.1935 | AS14: {=('1100'!K14) / 100} -> 0.2126 | AT14: {=('1100'!A14) / 100} -> 0.501 | AU14: {=('1100'!B14) / 100} -> 0.464 | AV14: {=('1100'!C14) / 100} -> 0.495 | AW14: {=('1100'!D14) / 100} -> 0.469 | AX14: {=('1100'!E14) / 100} -> 0.476 | AY14: 173249000 | AZ14: 141890000 | BA14: 111729000 | BB14: 100090000 | BC14: 104069000 | BD14: 45361000 | BE14: 44299000 | BF14: 32113000 | BG14: 28873000 | BH14: 22757000 | BI14: 182684000 | BJ14: 172301000 | BK14: 136683000 | BL14: 113366000 | BM14: 111722000 | BN14: 91450000 | BO14: 79976000 | BP14: 67633000 | BQ14: 53215000 | BR14: 53231000
A15: Attendo | B15: 5590267885 | C15: SE0007666110 | D15: SWE | E15: Företagstjänster | F15: 0.096 | G15: 0.1035 | H15: 0.1035 | I15: 0.1075 | J15: 0.0895 | K15: 0.085 | L15: 0.084 | M15: 0.022 | N15: 0.005 | O15: 0.018 | P15: -0.00255 | Q15: -0.00029762 | R15: 0 | S15: 0.0076779 | T15: 0.0346414 | U15: 0 | V15: 0 | W15: 0 | X15: =821*1000 -> 821000 | Y15: 0 | Z15: 21516 | AA15: 20821 | AB15: 19041 | AC15: 18178 | AD15: 16499 | AE15: 3045000 | AF15: 2174000 | AG15: 2166000 | AH15: 974000 | AI15: 1940000 | AJ15: 4.4344828 | AK15: 6.3610856 | AL15: 5.9949215 | AM15: 13.519507 | AN15: 6.0752577 | AO15: {=('1100'!G15) / 100} -> 0.0744 | AP15: {=('1100'!H15) / 100} -> 0.0426 | AQ15: {=('1100'!I15) / 100} -> 0.0589 | AR15: {=('1100'!J15) / 100} -> -0.0218 | AS15: {=('1100'!K15) / 100} -> 0.0567 | AT15: {=('1100'!A15) / 100} -> 0.234 | AU15: {=('1100'!B15) / 100} -> 0.224 | AV15: {=('1100'!C15) / 100} -> 0.234 | AW15: {=('1100'!D15) / 100} -> 0.242 | AX15: {=('1100'!E15) / 100} -> 0.288 | AY15: 17327000 | AZ15: 14557000 | BA15: 12891000 | BB15: 12361000 | BC15: 12045000 | BD15: 7197000 | BE15: 7204000 | BF15: 6878000 | BG15: 6644000 | BH15: 7446000 | BI15: 22893000 | BJ15: 22325000 | BK15: 21076000 | BL15: 20072000 | BM15: 20270000 | BN15: 5363000 | BO15: 5001000 | BP15: 4932000 | BQ15: 4849000 | BR15: 5831000
A16: Axfood AB | B16: 5565420824 | C16: SE0006993770 | D16: SWE | E16: Företagstjänster | F16: 0.075 | G16: 0.072 | H16: 0.069 | I16: 0.068 | J16: 0.068 | K16: 0.085 | L16: 0.084 | M16: 0.022 | N16: 0.005 | O16: 0.018 | P16: -0.00255 | Q16: -0.00029762 | R16: 0 | S16: 0.0076779 | T16: 0.0346414 | U16: 0 | V16: 0 | W16: 0 | X16: 0 | Y16: 0 | Z16: 13185 | AA16: 12772 | AB16: 12202 | AC16: 6120 | AD16: 10854 | AE16: 6345000 | AF16: 5682000 | AG16: 5103000 | AH16: 4762000 | AI16: 4434000 | AJ16: 1.3951143 | AK16: 1.5281591 | AL16: 0.962767 | AM16: 0.97270055 | AN16: 1.2525936 | AO16: {=('1100'!G16) / 100} -> 0.0422 | AP16: {=('1100'!H16) / 100} -> 0.0426 | AQ16: {=('1100'!I16) / 100} -> 0.0469 | AR16: {=('1100'!J16) / 100} -> 0.047 | AS16: {=('1100'!K16) / 100} -> 0.0452 | AT16: {=('1100'!A16) / 100} -> 0.229 | AU16: {=('1100'!B16) / 100} -> 0.231 | AV16: {=('1100'!C16) / 100} -> 0.209 | AW16: {=('1100'!D16) / 100} -> 0.23 | AX16: {=('1100'!E16) / 100} -> 0.232 | AY16: 81854000 | AZ16: 74508000 | BA16: 58679000 | BB16: 54328000 | BC16: 51263000 | BD16: 3606000 | BE16: 3526000 | BF16: 3846000 | BG16: 2769000 | BH16: 2767000 | BI16: 30018000 | BJ16: 28618000 | BK16: 23731000 | BL16: 18814000 | BM16: 17293000 | BN16: 6878000 | BO16: 6609000 | BP16: 4952000 | BQ16: 4331000 | BR16: 4020000
A17: Beijer Ref AB (publ) | B17: 5560408113 | C17: SE0015949748 | D17: SWE | E17: Företagstjänster | F17: 0.082 | G17: 0.084 | H17: 0.0913 | I17: 0.0826 | J17: 0.0811 | K17: 0.085 | L17: 0.084 | M17: 0.022 | N17: 0.005 | O17: 0.018 | P17: -0.00255 | Q17: -0.00029762 | R17: 0 | S17: 0.0076779 | T17: 0.0346414 | U17: 0 | V17: 0 | W17: 0 | X17: 0 | Y17: 0 | Z17: 6024 | AA17: 4720 | AB17: 4134 | AC17: 3856 | AD17: 3869 | AE17: 4031000 | AF17: 2471000 | AG17: 1834707 | AH17: 1477071 | AI17: 1654569 | AJ17: 2.3872488 | AK17: 2.8765682 | AL17: 2.7523408 | AM17: 2.6134262 | AN17: 1.2443863 | AO17: {=('1100'!G17) / 100} -> 0.1044 | AP17: {=('1100'!H17) / 100} -> 0.0872 | AQ17: {=('1100'!I17) / 100} -> 0.0814 | AR17: {=('1100'!J17) / 100} -> 0.0742 | AS17: {=('1100'!K17) / 100} -> 0.0838 | AT17: {=('1100'!A17) / 100} -> 0.544 | AU17: {=('1100'!B17) / 100} -> 0.302 | AV17: {=('1100'!C17) / 100} -> 0.338 | AW17: {=('1100'!D17) / 100} -> 0.387 | AX17: {=('1100'!E17) / 100} -> 0.387 | AY17: 32267000 | AZ17: 22783000 | BA17: 16952538 | BB17: 14087258 | BC17: 14845604 | BD17: 11891000 | BE17: 4416000 | BF17: 2667506 | BG17: 1563041 | BH17: 1559618 | BI17: 39170000 | BJ17: 21864000 | BK17: 15299967 | BL17: 11400519 | BM17: 11078776 | BN17: 21324000 | BO17: 6603000 | BP17: 5172655 | BQ17: 4412320 | BR17: 4282238
A18: Bergman & Beving Aktiebolag | B18: 5560348590 | C18: SE0000101362 | D18: SWE | E18: Företagstjänster | F18: =0.1 -> 0.1 | G18: =0.1 -> 0.1 | H18: N/A | I18: N/A | J18: =0.1 -> 0.1 | K18: 0.085 | L18: 0.084 | M18: 0.022 | N18: 0.005 | O18: 0.018 | P18: -0.00255 | Q18: -0.00029762 | R18: 0 | S18: 0.0076779 | T18: 0.0346414 | U18: 0 | V18: 0 | W18: 0 | X18: 0 | Y18: 0 | Z18: 1335 | AA18: 1283 | AB18: 1195 | AC18: 1079 | AD18: 1085 | AE18: 656000 | AF18: 571000 | AG18: 503000 | AH18: 426000 | AI18: 353000 | AJ18: 2.7408537 | AK18: 2.7478109 | AL18: 2.3200795 | AM18: 2.3262911 | AN18: 2.6260623 | AO18: {=('1100'!G18) / 100} -> 0.0824 | AP18: {=('1100'!H18) / 100} -> 0.0733 | AQ18: {=('1100'!I18) / 100} -> 0.0658 | AR18: {=('1100'!J18) / 100} -> 0.0585 | AS18: {=('1100'!K18) / 100} -> 0.0488 | AT18: {=('1100'!A18) / 100} -> 0.348 | AU18: {=('1100'!B18) / 100} -> 0.379 | AV18: {=('1100'!C18) / 100} -> 0.362 | AW18: {=('1100'!D18) / 100} -> 0.344 | AX18: {=('1100'!E18) / 100} -> 0.343 | AY18: 4762000 | AZ18: 4793000 | BA18: 4586000 | BB18: 4326000 | BC18: 4087000 | BD18: 2018000 | BE18: 1815000 | BF18: 1667000 | BG18: 1609000 | BH18: 1570000 | BI18: 6062000 | BJ18: 5749000 | BK18: 5295000 | BL18: 4941000 | BM18: 4757000 | BN18: 2108000 | BO18: 2181000 | BP18: 1915000 | BQ18: 1701000 | BR18: 1631000
A19: BHG Group AB | B19: 5590770763 | C19: SE0010948588 | D19: SWE | E19: Företagstjänster | F19: 0.08 | G19: 0.08 | H19: 0.08 | I19: 0.08 | J19: 0.096 | K19: 0.085 | L19: 0.084 | M19: 0.022 | N19: 0.005 | O19: 0.018 | P19: -0.00255 | Q19: -0.00029762 | R19: 0 | S19: 0.0076779 | T19: 0.0346414 | U19: 0 | V19: 0 | W19: 0 | X19: 0 | Y19: 0 | Z19: 2001 | AA19: 2693 | AB19: 2860 | AC19: 1737 | AD19: 1188 | AE19: -676500 | AF19: 364600 | AG19: 1082100 | AH19: 902800 | AI19: 467000 | AJ19: -3.3232816 | AK19: 11.02441 | AL19: 4.6416228 | AM19: 3.8108108 | AN19: 4.1391863 | AO19: {=('1100'!G19) / 100} -> -0.1141 | AP19: {=('1100'!H19) / 100} -> 0.008 | AQ19: {=('1100'!I19) / 100} -> 0.0577 | AR19: {=('1100'!J19) / 100} -> 0.0737 | AS19: {=('1100'!K19) / 100} -> 0.0467 | AT19: {=('1100'!A19) / 100} -> 0.555 | AU19: {=('1100'!B19) / 100} -> 0.533 | AV19: {=('1100'!C19) / 100} -> 0.383 | AW19: {=('1100'!D19) / 100} -> 0.323 | AX19: {=('1100'!E19) / 100} -> 0.48 | AY19: 11810800 | AZ19: 13450700 | BA19: 12681600 | BB19: 8973800 | BC19: 6212900 | BD19: 5899700 | BE19: 6480900 | BF19: 6318700 | BG19: 4395100 | BH19: 2896700 | BI19: 11423300 | BJ19: 14281400 | BK19: 13612300 | BL19: 8629700 | BM19: 6018200 | BN19: 6342600 | BO19: 7613900 | BP19: 5211900 | BQ19: 2787200 | BR19: 2889700
A20: Bilia AB | B20: 5561125690 | C20: SE0009921588 | D20: SWE | E20: Företagstjänster | F20: 0.1121 | G20: 0.0898 | H20: 0.0627 | I20: 0.0535 | J20: 0.0522 | K20: 0.085 | L20: 0.084 | M20: 0.022 | N20: 0.005 | O20: 0.018 | P20: -0.00255 | Q20: -0.00029762 | R20: 0 | S20: 0.0076779 | T20: 0.0346414 | U20: 0 | V20: 0 | W20: =35*1000 -> 35000 | X20: 0 | Y20: =13*1000 -> 13000 | Z20: 4476 | AA20: 4195 | AB20: 4385 | AC20: 4097 | AD20: 4298 | AE20: 3032000 | AF20: 3595000 | AG20: 3195000 | AH20: 2068000 | AI20: 2393000 | AJ20: 2.3060686 | AK20: 1.7148818 | AL20: 2.1480438 | AM20: 3.9366538 | AN20: 2.7760134 | AO20: {=('1100'!G20) / 100} -> 0.0394 | AP20: {=('1100'!H20) / 100} -> 0.0621 | AQ20: {=('1100'!I20) / 100} -> 0.0559 | AR20: {=('1100'!J20) / 100} -> 0.0468 | AS20: {=('1100'!K20) / 100} -> 0.0399 | AT20: {=('1100'!A20) / 100} -> 0.25 | AU20: {=('1100'!B20) / 100} -> 0.244 | AV20: {=('1100'!C20) / 100} -> 0.257 | AW20: {=('1100'!D20) / 100} -> 0.242 | AX20: {=('1100'!E20) / 100} -> 0.198 | AY20: 38560000 | AZ20: 35760000 | BA20: 35548000 | BB20: 30187000 | BC20: 29532000 | BD20: 1496000 | BE20: 1520000 | BF20: 1175000 | BG20: 812000 | BH20: 847000 | BI20: 19395000 | BJ20: 20001000 | BK20: 17200000 | BL20: 16416000 | BM20: 16081000 | BN20: 4841000 | BO20: 4887000 | BP20: 4417000 | BQ20: 3968000 | BR20: 3186000
A21: Billerud Aktiebolag (publ) | B21: 5560255001 | C21: SE0000862997 | D21: SWE | E21: Företagstjänster | F21: 0.0994 | G21: 0.1 | H21: 0.1 | I21: 0.11 | J21: 0.11 | K21: 0.085 | L21: 0.084 | M21: 0.022 | N21: 0.005 | O21: 0.018 | P21: -0.00255 | Q21: -0.00029762 | R21: 0 | S21: 0.0076779 | T21: 0.0346414 | U21: 0 | V21: 0 | W21: 0 | X21: 0 | Y21: 0 | Z21: 6134 | AA21: 5525 | AB21: 4370 | AC21: 4468 | AD21: 4596 | AE21: 3314000 | AF21: 8167000 | AG21: 3901000 | AH21: 2712000 | AI21: 2830000 | AJ21: 2.7012674 | AK21: 0.92555406 | AL21: 2.252243 | AM21: 4.0855457 | AN21: 4.2787986 | AO21: {=('1100'!G21) / 100} -> 0.0152 | AP21: {=('1100'!H21) / 100} -> 0.1423 | AQ21: {=('1100'!I21) / 100} -> 0.076 | AR21: {=('1100'!J21) / 100} -> 0.0337 | AS21: {=('1100'!K21) / 100} -> 0.059 | AT21: {=('1100'!A21) / 100} -> 0.562 | AU21: {=('1100'!B21) / 100} -> 0.569 | AV21: {=('1100'!C21) / 100} -> 0.528 | AW21: {=('1100'!D21) / 100} -> 0.531 | AX21: {=('1100'!E21) / 100} -> 0.527 | AY21: 40634000 | AZ21: 43754000 | BA21: 26802000 | BB21: 24228000 | BC21: 24614000 | BD21: 2215000 | BE21: 2225000 | BF21: 1952000 | BG21: 1951000 | BH21: 2011000 | BI21: 47926000 | BJ21: 51415000 | BK21: 37978000 | BL21: 36360000 | BM21: 36924000 | BN21: 26945000 | BO21: 29254000 | BP21: 20041000 | BQ21: 19294000 | BR21: 19462000
A22: BioGaia AB | B22: 5563808723 | C22: SE0017769995 | D22: SWE | E22: Partihandel | F22: 0.0965 | G22: 0.0954 | H22: 0.0772 | I22: 0.0865 | J22: 0.05 | K22: 0.085 | L22: 0.084 | M22: 0.022 | N22: 0.005 | O22: 0.018 | P22: -0.00255 | Q22: -0.00029762 | R22: 0 | S22: 0.0076779 | T22: 0.0346414 | U22: 0 | V22: 0 | W22: 0 | X22: 0 | Y22: 0 | Z22: 213 | AA22: 203 | AB22: 161 | AC22: 157 | AD22: 153 | AE22: 466773 | AF22: 375659 | AG22: 258989 | AH22: 238109 | AI22: 252039 | AJ22: 0.22947128 | AK22: 0.20379387 | AL22: 0.47775388 | AM22: 0.13353128 | AN22: 0.1318288 | AO22: {=('1100'!G22) / 100} -> 0.3738 | AP22: {=('1100'!H22) / 100} -> 0.4103 | AQ22: {=('1100'!I22) / 100} -> 0.3233 | AR22: {=('1100'!J22) / 100} -> 0.3056 | AS22: {=('1100'!K22) / 100} -> 0.3162 | AT22: {=('1100'!A22) / 100} -> 0.87 | AU22: {=('1100'!B22) / 100} -> 0.891 | AV22: {=('1100'!C22) / 100} -> 0.882 | AW22: {=('1100'!D22) / 100} -> 0 | AX22: {=('1100'!E22) / 100} -> 0.763 | AY22: 1298729 | AZ22: 1131446 | BA22: 796714 | BB22: 748161 | BC22: 768347 | BD22: 165174 | BE22: 171517 | BF22: 149227 | BG22: 530000 | BH22: 530000 | BI22: 2333190 | BJ22: 2213966 | BK22: 2128054 | BL22: 1913282 | BM22: 665900 | BN22: 2030342 | BO22: 1972416 | BP22: 1877365 | BQ22: 699349 | BR22: 507872
A23: Biotage AB | B23: 5565393138 | C23: SE0000454746 | D23: SWE | E23: Företagstjänster | F23: =0.1126 -> 0.1126 | G23: =0.122 -> 0.122 | H23: =0.0998 -> 0.0998 | I23: =0.1172 -> 0.1172 | J23: =0.129 -> 0.129 | K23: 0.085 | L23: 0.084 | M23: 0.022 | N23: 0.005 | O23: 0.018 | P23: -0.00255 | Q23: -0.00029762 | R23: 0 | S23: 0.0076779 | T23: 0.0346414 | U23: 0 | V23: 0 | W23: 0 | X23: 0 | Y23: 0 | Z23: 674 | AA23: 517 | AB23: 497 | AC23: 463 | AD23: 440 | AE23: 463 000 | AF23: 429 000 | AG23: 347 000 | AH23: 279 832 | AI23: 282 492 | AJ23: 1.222 | AK23: 0.653 | AL23: 0.648 | AM23: 0.811 | AN23: 0.878 | AO23: {=('1100'!G23) / 100} -> 0.1847 | AP23: {=('1100'!H23) / 100} -> 0.2312 | AQ23: {=('1100'!I23) / 100} -> 0.2281 | AR23: {=('1100'!J23) / 100} -> 0.2116 | AS23: {=('1100'!K23) / 100} -> 0.1951 | AT23: {=('1100'!A23) / 100} -> 0.742 | AU23: {=('1100'!B23) / 100} -> 0.7 | AV23: {=('1100'!C23) / 100} -> 0.688 | AW23: {=('1100'!D23) / 100} -> 0.69 | AX23: {=('1100'!E23) / 100} -> 0.655 | AY23: 1878000 | AZ23: 1603000 | BA23: 1249000 | BB23: 1112785 | BC23: 1104175 | BD23: 2 391 000 | BE23: 794 000 | BF23: 741 000 | BG23: 290209 | BH23: 315869 | BI23: 4931000 | BJ23: 2339000 | BK23: 1992000 | BL23: 1434441 | BM23: 1335687 | BN23: 3657000 | BO23: 1637000 | BP23: 1371000 | BQ23: 990038 | BR23: 875503
A24: Boliden AB | B24: 5560514142 | C24: SE0020050417 | D24: SWE | E24: Företagstjänster | F24: 0.09 | G24: 0.09 | H24: 0.09 | I24: 0.09 | J24: 0.09 | K24: 0.085 | L24: 0.084 | M24: 0.022 | N24: 0.005 | O24: 0.018 | P24: -0.00255 | Q24: -0.00029762 | R24: 0 | S24: 0.0076779 | T24: 0.0346414 | U24: 0 | V24: 0 | W24: 0 | X24: 0 | Y24: 0 | Z24: 5664 | AA24: 6226 | AB24: 6167 | AC24: 6071 | AD24: 5997 | AE24: 14533000 | AF24: 22058000 | AG24: 16703000 | AH24: 14628000 | AI24: 12689000 | AJ24: 1.2378724 | AK24: 1.0232115 | AL24: 0.56947854 | AM24: 0.64376538 | AN24: 0.69461739 | AO24: {=('1100'!G24) / 100} -> 0.1081 | AP24: {=('1100'!H24) / 100} -> 0.1845 | AQ24: {=('1100'!I24) / 100} -> 0.1615 | AR24: {=('1100'!J24) / 100} -> 0.1587 | AS24: {=('1100'!K24) / 100} -> 0.1524 | AT24: {=('1100'!A24) / 100} -> 0.553 | AU24: {=('1100'!B24) / 100} -> 0.605 | AV24: {=('1100'!C24) / 100} -> 0.632 | AW24: {=('1100'!D24) / 100} -> 0.629 | AX24: {=('1100'!E24) / 100} -> 0.624 | AY24: 79465000 | AZ24: 87343000 | BA24: 69064000 | BB24: 56663000 | BC24: 50290000 | BD24: 3240000 | BE24: 3295000 | BF24: 3153000 | BG24: 3077000 | BH24: 3204000 | BI24: 101957000 | BJ24: 96376000 | BK24: 80549000 | BL24: 72492000 | BM24: 66424000 | BN24: 56404000 | BO24: 58311000 | BP24: 50867000 | BQ24: 45625000 | BR24: 41429000
A25: Boozt AB | B25: 5567935183 | C25: SE0009888738 | D25: SWE | E25: Företagstjänster | F25: 0.117 | G25: 0.114 | H25: 0.103 | I25: 0.105 | J25: 0.105 | K25: 0.085 | L25: 0.084 | M25: 0.022 | N25: 0.005 | O25: 0.018 | P25: -0.00255 | Q25: -0.00029762 | R25: 0 | S25: 0.0076779 | T25: 0.0346414 | U25: 0 | V25: 0 | W25: 0 | X25: 0 | Y25: 0 | Z25: 1093 | AA25: 1253 | AB25: 1049 | AC25: 375 | AD25: 337 | AE25: 551000 | AF25: 475600 | AG25: 431500 | AH25: 344100 | AI25: 198000 | AJ25: 1.6297641 | AK25: 1.8467199 | AL25: 1.7251448 | AM25: 1.5896542 | AN25: 2.4838384 | AO25: {=('1100'!G25) / 100} -> 0.0418 | AP25: {=('1100'!H25) / 100} -> 0.0383 | AQ25: {=('1100'!I25) / 100} -> 0.0455 | AR25: {=('1100'!J25) / 100} -> 0.0418 | AS25: {=('1100'!K25) / 100} -> 0.0268 | AT25: {=('1100'!A25) / 100} -> 0.457 | AU25: {=('1100'!B25) / 100} -> 0.418 | AV25: {=('1100'!C25) / 100} -> 0.43 | AW25: {=('1100'!D25) / 100} -> 0.473 | AX25: {=('1100'!E25) / 100} -> 0.379 | AY25: 7755000 | AZ25: 6747900 | BA25: 5818500 | BB25: 4359300 | BC25: 3424900 | BD25: 298000 | BE25: 299800 | BF25: 275500 | BG25: 9400 | BH25: 9800 | BI25: 5959000 | BJ25: 5992200 | BK25: 5057800 | BL25: 4031800 | BM25: 2487200 | BN25: 2721000 | BO25: 2502600 | BP25: 2176500 | BQ25: 1908100 | BR25: 942500
A26: Bravida Holding AB | B26: 5568915390 | C26: SE0007491303 | D26: SWE | E26: Företagstjänster | F26: 0.106 | G26: 0.109 | H26: 0.074 | I26: 0.079 | J26: 0.071 | K26: 0.085 | L26: 0.084 | M26: 0.022 | N26: 0.005 | O26: 0.018 | P26: -0.00255 | Q26: -0.00029762 | R26: 0 | S26: 0.0076779 | T26: 0.0346414 | U26: 0 | V26: 0 | W26: 0 | X26: 0 | Y26: 0 | Z26: 13833 | AA26: 13078 | AB26: 11864 | AC26: 11906 | AD26: 11722 | AE26: 2322000 | AF26: 2164000 | AG26: 1944000 | AH26: 1782000 | AI26: 1641000 | AJ26: 0.99612403 | AK26: 0.94269871 | AL26: 0.59053498 | AM26: 0.96352413 | AN26: 0.78549665 | AO26: {=('1100'!G26) / 100} -> 0.0604 | AP26: {=('1100'!H26) / 100} -> 0.0653 | AQ26: {=('1100'!I26) / 100} -> 0.0695 | AR26: {=('1100'!J26) / 100} -> 0.0644 | AS26: {=('1100'!K26) / 100} -> 0.0603 | AT26: {=('1100'!A26) / 100} -> 0.338 | AU26: {=('1100'!B26) / 100} -> 0.351 | AV26: {=('1100'!C26) / 100} -> 0.349 | AW26: {=('1100'!D26) / 100} -> 0.343 | AX26: {=('1100'!E26) / 100} -> 0.338 | AY26: 29423000 | AZ26: 26303000 | BA26: 21876000 | BB26: 21147000 | BC26: 20404000 | BD26: 11000000 | BE26: 10439000 | BF26: 9500000 | BG26: 8904000 | BH26: 8731000 | BI26: 24333000 | BJ26: 22472000 | BK26: 19516000 | BL26: 17053000 | BM26: 16510000 | BN26: 8229000 | BO26: 7895000 | BP26: 6815000 | BQ26: 5855000 | BR26: 5586000
A27: BTS Group AB | B27: 5565667119 | C27: SE0000805426 | D27: SWE | E27: Juridik, ekonomi & konsulttjänster | F27: 0.113 | G27: 0.11 | H27: 0.1 | I27: 0.105 | J27: 0.105 | K27: 0.085 | L27: 0.084 | M27: 0.022 | N27: 0.005 | O27: 0.018 | P27: -0.00255 | Q27: -0.00029762 | R27: 0 | S27: 0.0076779 | T27: 0.0346414 | U27: 0 | V27: 0 | W27: 0 | X27: 0 | Y27: 0 | Z27: 1152 | AA27: 1129 | AB27: 936 | AC27: 843 | AD27: 779 | AE27: 421917 | AF27: 419946 | AG27: 409153 | AH27: 155429 | AI27: 311185 | AJ27: 1.9821221 | AK27: 0.76621042 | AL27: 1.3260174 | AM27: 2.5912088 | AN27: 0.73989749 | AO27: {=('1100'!G27) / 100} -> 0.12 | AP27: {=('1100'!H27) / 100} -> 0.121 | AQ27: {=('1100'!I27) / 100} -> 0.1597 | AR27: {=('1100'!J27) / 100} -> 0.045 | AS27: {=('1100'!K27) / 100} -> 0.1216 | AT27: {=('1100'!A27) / 100} -> 0.44 | AU27: {=('1100'!B27) / 100} -> 0.44 | AV27: {=('1100'!C27) / 100} -> 0.395 | AW27: {=('1100'!D27) / 100} -> 0.362 | AX27: {=('1100'!E27) / 100} -> 0.449 | AY27: 2682892 | AZ27: 2529634 | BA27: 1966456 | BB27: 1464155 | BC27: 1865499 | BD27: 1103993 | BE27: 908882 | BF27: 830094 | BG27: 548759 | BH27: 535916 | BI27: 2956421 | BJ27: 2758519 | BK27: 2491837 | BL27: 1960087 | BM27: 1868812 | BN27: 1300654 | BO27: 1213930 | BP27: 983250 | BQ27: 709857 | BR27: 839677
A28: Bufab AB (publ) | B28: 5566856240 | C28: SE0005677135 | D28: SWE | E28: Företagstjänster | F28: 0.099 | G28: 0.08 | H28: 0.08 | I28: =0.08 -> 0.08 | J28: 0.075 | K28: 0.085 | L28: 0.084 | M28: 0.022 | N28: 0.005 | O28: 0.018 | P28: -0.00255 | Q28: -0.00029762 | R28: 0 | S28: 0.0076779 | T28: 0.0346414 | U28: 0 | V28: 0 | W28: 0 | X28: 0 | Y28: 0 | Z28: 1834 | AA28: 1754 | AB28: 1423 | AC28: 1352 | AD28: 1296 | AE28: 1252000 | AF28: 1170000 | AG28: 856000 | AH28: 636000 | AI28: 516000 | AJ28: 2.9376997 | AK28: 3.4820513 | AL28: 3.1799065 | AM28: 3.3160377 | AN28: 5.0505368 | AO28: {=('1100'!G28) / 100} -> 0.1139 | AP28: {=('1100'!H28) / 100} -> 0.1121 | AQ28: {=('1100'!I28) / 100} -> 0.1131 | AR28: {=('1100'!J28) / 100} -> 0.0957 | AS28: {=('1100'!K28) / 100} -> 0.0862 | AT28: {=('1100'!A28) / 100} -> 0.397 | AU28: {=('1100'!B28) / 100} -> 0.322 | AV28: {=('1100'!C28) / 100} -> 0.362 | AW28: {=('1100'!D28) / 100} -> 0.387 | AX28: {=('1100'!E28) / 100} -> 0.333 | AY28: 8736000 | AZ28: 8660000 | BA28: 5915000 | BB28: 4811000 | BC28: 4387000 | BD28: 2842000 | BE28: 2857000 | BF28: 1994000 | BG28: 216000 | BH28: 1771000 | BI28: 8600000 | BJ28: 9436000 | BK28: 6573000 | BL28: 4991000 | BM28: 5250000 | BN28: 3418000 | BO28: 3036000 | BP28: 2377000 | BQ28: 1931000 | BR28: 1749000
A29: Byggmax Group AB | B29: 5566563531 | C29: SE0003303627 | D29: SWE | E29: Fastighetsverksamhet | F29: 0.154 | G29: 0.105 | H29: 0.086 | I29: 0.088 | J29: 0.073 | K29: 0.085 | L29: 0.084 | M29: 0.022 | N29: 0.005 | O29: 0.018 | P29: -0.00255 | Q29: -0.00029762 | R29: 0 | S29: 0.0076779 | T29: 0.0346414 | U29: 0 | V29: 0 | W29: 0 | X29: 0 | Y29: 0 | Z29: 1289 | AA29: 1387 | AB29: 1370 | AC29: 1212 | AD29: 1103 | AE29: 781000 | AF29: 1063000 | AG29: 1369000 | AH29: 1136000 | AI29: 694400 | AJ29: 3.1549296 | AK29: 1.3715898 | AL29: 1.5631848 | AM29: 1.4339789 | AN29: 2.0452189 | AO29: {=('1100'!G29) / 100} -> 0.0275 | AP29: {=('1100'!H29) / 100} -> 0.0678 | AQ29: {=('1100'!I29) / 100} -> 0.1125 | AR29: {=('1100'!J29) / 100} -> 0.1012 | AS29: {=('1100'!K29) / 100} -> 0.0463 | AT29: {=('1100'!A29) / 100} -> 0.383 | AU29: {=('1100'!B29) / 100} -> 0.363 | AV29: {=('1100'!C29) / 100} -> 0.371 | AW29: {=('1100'!D29) / 100} -> 0.399 | AX29: {=('1100'!E29) / 100} -> 0.298 | AY29: 6152000 | AZ29: 7298000 | BA29: 7670000 | BB29: 6827000 | BC29: 5286900 | BD29: 2015000 | BE29: 2024000 | BF29: 1963000 | BG29: 2006000 | BH29: 1808300 | BI29: 6165000 | BJ29: 6508000 | BK29: 6073000 | BL29: 4933000 | BM29: 5044500 | BN29: 2361000 | BO29: 2361000 | BP29: 2252000 | BQ29: 1968000 | BR29: 1500800
A30: CellaVision AB | B30: 5565000998 | C30: SE0000683484 | D30: SWE | E30: Utbildning, forskning & utveckling | F30: 0.101 | G30: 0.094 | H30: =0.104 -> 0.104 | I30: =0.104 -> 0.104 | J30: =0.104 -> 0.104 | K30: 0.085 | L30: 0.084 | M30: 0.022 | N30: 0.005 | O30: 0.018 | P30: -0.00255 | Q30: -0.00029762 | R30: 0 | S30: 0.0076779 | T30: 0.0346414 | U30: 0 | V30: 0 | W30: 0 | X30: 0 | Y30: 0 | Z30: 242 | AA30: 242 | AB30: 201 | AC30: 182 | AD30: 125 | AE30: 206814 | AF30: 194994 | AG30: 196170 | AH30: 142311 | AI30: 146731 | AJ30: 0.13859797 | AK30: 0.3095685 | AL30: 0.73301728 | AM30: 0.91546683 | AN30: 1.1004219 | AO30: {=('1100'!G30) / 100} -> 0.2576 | AP30: {=('1100'!H30) / 100} -> 0.2563 | AQ30: {=('1100'!I30) / 100} -> 0.2938 | AR30: {=('1100'!J30) / 100} -> 0.249 | AS30: {=('1100'!K30) / 100} -> 0.2871 | AT30: {=('1100'!A30) / 100} -> 0.771 | AU30: {=('1100'!B30) / 100} -> 0.72 | AV30: {=('1100'!C30) / 100} -> 0.658 | AW30: {=('1100'!D30) / 100} -> 0.643 | AX30: {=('1100'!E30) / 100} -> 0.543 | AY30: 677292 | AZ30: 639340 | BA30: 565552 | BB30: 471443 | BC30: 461772 | BD30: 123780 | BE30: 124141 | BF30: 114085 | BG30: 111972 | BH30: 115121 | BI30: 928712 | BJ30: 891748 | BK30: 825212 | BL30: 668025 | BM30: 641709 | BN30: 716389 | BO30: 641628 | BP30: 543280 | BQ30: 429617 | BR30: 348373
A31: Cint Group AB (publ) | B31: 5590403217 | C31: SE0015483276 | D31: SWE | E31: Juridik, ekonomi & konsulttjänster | F31: =0.131 -> 0.131 | G31: =0.111 -> 0.111 | H31: 0.091 | I31: =0.108 -> 0.108 | J31: =0.108 -> 0.108 | K31: 0.085 | L31: 0.084 | M31: 0.022 | N31: 0.005 | O31: 0.018 | P31: -0.00255 | Q31: -0.00029762 | R31: 0 | S31: 0.0076779 | T31: 0.0346414 | U31: =412.213*1000 -> 412213 | V31: =340.769*1000 -> 340769 | W31: 0 | X31: 0 | Y31: 0 | Z31: 885 | AA31: 830 | AB31: 891 | AC31: 229 | AD31: 199 | AE31: 287 386 | AF31: - 3 481 646 | AG31: 60 548 | AH31: 133 557 | AI31: 50 472 | AJ31: 6.075 | AK31: - 0,608 | AL31: 32.181 | AM31: 1.305 | AN31: 10.14 | AO31: {=('1100'!G31) / 100} -> -1.68 | AP31: {=('1100'!H31) / 100} -> -1.2 | AQ31: {=('1100'!I31) / 100} -> -0.0066 | AR31: {=('1100'!J31) / 100} -> 0.0643 | AS31: {=('1100'!K31) / 100} -> -0.01 | AT31: {=('1100'!A31) / 100} -> 0.585 | AU31: {=('1100'!B31) / 100} -> 0.736 | AV31: {=('1100'!C31) / 100} -> 0.791 | AW31: {=('1100'!D31) / 100} -> 0.697 | AX31: {=('1100'!E31) / 100} -> 0.559 | AY31: 3161972 | AZ31: 3465987 | BA31: 1533240 | BB31: 1050200 | BC31: 838758 | BD31: 1726083 | BE31: 6670055 | BF31: 9280734 | BG31: 1010594 | BH31: 1053369 | BI31: 6945375 | BJ31: 12851240 | BK31: 14880340 | BL31: 2003890 | BM31: 2010770 | BN31: 4060848 | BO31: 9453619 | BP31: 11766576 | BQ31: 1396403 | BR31: 1123484
A32: Cloetta AB | B32: 5563088144 | C32: SE0002626861 | D32: SWE | E32: Företagstjänster | F32: 0.108 | G32: 0.11 | H32: 0.067 | I32: 0.065 | J32: 0.072 | K32: 0.085 | L32: 0.084 | M32: 0.022 | N32: 0.005 | O32: 0.018 | P32: -0.00255 | Q32: -0.00029762 | R32: 0 | S32: 0.0076779 | T32: 0.0346414 | U32: 0 | V32: 0 | W32: 0 | X32: 0 | Y32: 0 | Z32: 2582 | AA32: 2598 | AB32: 2599 | AC32: 2653 | AD32: 2629 | AE32: 1030000 | AF32: 728000 | AG32: 825000 | AH32: 737000 | AI32: 1028000 | AJ32: 3.4504854 | AK32: 3.1277473 | AL32: 2.6206061 | AM32: 0.15061058 | AN32: 1.6974708 | AO32: {=('1100'!G32) / 100} -> 0.104 | AP32: {=('1100'!H32) / 100} -> 0.0799 | AQ32: {=('1100'!I32) / 100} -> 0.1004 | AR32: {=('1100'!J32) / 100} -> 0.0817 | AS32: {=('1100'!K32) / 100} -> 0.1123 | AT32: {=('1100'!A32) / 100} -> 0.477 | AU32: {=('1100'!B32) / 100} -> 0.484 | AV32: {=('1100'!C32) / 100} -> 0.473 | AW32: {=('1100'!D32) / 100} -> 0.451 | AX32: {=('1100'!E32) / 100} -> 0.434 | AY32: 8301000 | AZ32: 6869000 | BA32: 6046000 | BB32: 5695000 | BC32: 6493000 | BD32: 2565000 | BE32: 2570000 | BF32: 2391000 | BG32: 2347000 | BH32: 2400000 | BI32: 10683000 | BJ32: 10316000 | BK32: 9549000 | BL32: 9257000 | BM32: 9660000 | BN32: 5098000 | BO32: 4994000 | BP32: 4515000 | BQ32: 4179000 | BR32: 4197000
A33: Concentric AB | B33: 5568284995 | C33: SE0003950864 | D33: SWE | E33: Juridik, ekonomi & konsulttjänster | F33: 0.1 | G33: 0.097 | H33: 0.076 | I33: 0.056 | J33: =0.07 -> 0.07 | K33: 0.085 | L33: 0.084 | M33: 0.022 | N33: 0.005 | O33: 0.018 | P33: -0.00255 | Q33: -0.00029762 | R33: 0 | S33: 0.0076779 | T33: 0.0346414 | U33: 0 | V33: 0 | W33: 0 | X33: 0 | Y33: 0 | Z33: 1282 | AA33: 1207 | AB33: 817 | AC33: 641 | AD33: 844 | AE33: 786000 | AF33: 865000 | AG33: 499000 | AH33: 362000 | AI33: 571000 | AJ33: 1.3231552 | AK33: 1.4809249 | AL33: 2.7835671 | AM33: 1.6298343 | AN33: 1.0262697 | AO33: {=('1100'!G33) / 100} -> 0.146 | AP33: {=('1100'!H33) / 100} -> 0.1711 | AQ33: {=('1100'!I33) / 100} -> 0.1924 | AR33: {=('1100'!J33) / 100} -> 0.1851 | AS33: {=('1100'!K33) / 100} -> 0.2391 | AT33: {=('1100'!A33) / 100} -> 0.507 | AU33: {=('1100'!B33) / 100} -> 0.461 | AV33: {=('1100'!C33) / 100} -> 0.386 | AW33: {=('1100'!D33) / 100} -> 0.521 | AX33: {=('1100'!E33) / 100} -> 0.536 | AY33: 4324000 | AZ33: 4160000 | BA33: 2236000 | BB33: 1583000 | BC33: 2106000 | BD33: 1422000 | BE33: 1455000 | BF33: 1303000 | BG33: 649000 | BH33: 656000 | BI33: 4306000 | BJ33: 4495000 | BK33: 3783000 | BL33: 2047000 | BM33: 2119000 | BN33: 2181000 | BO33: 2070000 | BP33: 1462000 | BQ33: 1067000 | BR33: 1136000
A34: Dometic Group AB (publ) | B34: 5568294390 | C34: SE0007691613 | D34: SWE | E34: Företagstjänster | F34: 0.096 | G34: 0.1272 | H34: 0.0816 | I34: 0.0841 | J34: 0.0942 | K34: 0.085 | L34: 0.084 | M34: 0.022 | N34: 0.005 | O34: 0.018 | P34: -0.00255 | Q34: -0.00029762 | R34: 0 | S34: 0.0076779 | T34: 0.0346414 | U34: 0 | V34: 0 | W34: 0 | X34: 0 | Y34: 0 | Z34: 8093 | AA34: 8834 | AB34: 7650 | AC34: 6868 | AD34: 7257 | AE34: 3297000 | AF34: 4057000 | AG34: 3775000 | AH34: 2489000 | AI34: 2952000 | AJ34: 7.3773127 | AK34: 5.5671679 | AL34: 6.0164238 | AM34: 6.6376055 | AN34: 5.3665312 | AO34: {=('1100'!G34) / 100} -> 0.1026 | AP34: {=('1100'!H34) / 100} -> 0.1028 | AQ34: {=('1100'!I34) / 100} -> 0.1333 | AR34: {=('1100'!J34) / 100} -> 0.1164 | AS34: {=('1100'!K34) / 100} -> 0.1281 | AT34: {=('1100'!A34) / 100} -> 0.48 | AU34: {=('1100'!B34) / 100} -> 0.46 | AV34: {=('1100'!C34) / 100} -> 0.431 | AW34: {=('1100'!D34) / 100} -> 0.431 | AX34: {=('1100'!E34) / 100} -> 0.473 | AY34: 27775000 | AZ34: 29908000 | BA34: 21594000 | BB34: 16271000 | BC34: 18571000 | BD34: 21267 | BE34: 22086000 | BF34: 20503000 | BG34: 13545000 | BH34: 14832000 | BI34: 54119000 | BJ34: 57451000 | BK34: 52030000 | BL34: 37615000 | BM34: 36681000 | BN34: 25992000 | BO34: 26415000 | BP34: 22447000 | BQ34: 16201000 | BR34: 17363000
A35: Duni AB | B35: 5565367488 | C35: SE0000616716 | D35: SWE | E35: Partihandel | F35: 0.125 | G35: 0.116 | H35: 0.097 | I35: 0.094 | J35: 0.079 | K35: 0.085 | L35: 0.084 | M35: 0.022 | N35: 0.005 | O35: 0.018 | P35: -0.00255 | Q35: -0.00029762 | R35: 0 | S35: 0.0076779 | T35: 0.0346414 | U35: 0 | V35: 0 | W35: =21*1000 -> 21000 | X35: 0 | Y35: =58*1000 -> 58000 | Z35: 2373 | AA35: 2402 | AB35: 2442 | AC35: 2450 | AD35: 2476 | AE35: 923000 | AF35: 604000 | AG35: 444000 | AH35: 358000 | AI35: 701000 | AJ35: 1.1213434 | AK35: 2.5182119 | AL35: 4.6711712 | AM35: 5.3156425 | AN35: 3.3338088 | AO35: {=('1100'!G35) / 100} -> 0.0885 | AP35: {=('1100'!H35) / 100} -> 0.0487 | AQ35: {=('1100'!I35) / 100} -> 0.0342 | AR35: {=('1100'!J35) / 100} -> 0.016 | AS35: {=('1100'!K35) / 100} -> 0.0739 | AT35: {=('1100'!A35) / 100} -> 0.495 | AU35: {=('1100'!B35) / 100} -> 0.438 | AV35: {=('1100'!C35) / 100} -> 0.411 | AW35: {=('1100'!D35) / 100} -> 0.44 | AX35: {=('1100'!E35) / 100} -> 0.41 | AY35: 7764000 | AZ35: 7056000 | BA35: 5195000 | BB35: 4622000 | BC35: 5571000 | BD35: 2110000 | BE35: 2136000 | BF35: 2010000 | BG35: 2011000 | BH35: 2054000 | BI35: 6913000 | BJ35: 7339000 | BK35: 6396000 | BL35: 5780000 | BM35: 6245000 | BN35: 3422000 | BO35: 3211000 | BP35: 2628000 | BQ35: 2542000 | BR35: 2563000
A36: Dustin Group AB | B36: 5567033062 | C36: SE0006625471 | D36: SWE | E36: Detaljhandel | F36: =0.089 -> 0.089 | G36: =0.089 -> 0.089 | H36: =0.085 -> 0.085 | I36: =0.082 -> 0.082 | J36: =0.082 -> 0.082 | K36: 0.085 | L36: 0.084 | M36: 0.022 | N36: 0.005 | O36: 0.018 | P36: -0.00255 | Q36: -0.00029762 | R36: 0 | S36: 0.0076779 | T36: 0.0346414 | U36: 0 | V36: 0 | W36: 0 | X36: 0 | Y36: 0 | Z36: 2409 | AA36: 2424 | AB36: 1858 | AC36: 1700 | AD36: 1644 | AE36: 885200 | AF36: 1165200 | AG36: 897300 | AH36: 684100 | AI36: 604700 | AJ36: 6.9055581 | AK36: 4.6637487 | AL36: 5.7362086 | AM36: 4.0342055 | AN36: 3.746982 | AO36: {=('1100'!G36) / 100} -> 0.0202 | AP36: {=('1100'!H36) / 100} -> 0.0322 | AQ36: {=('1100'!I36) / 100} -> 0.0364 | AR36: {=('1100'!J36) / 100} -> 0.0295 | AS36: {=('1100'!K36) / 100} -> 0.0391 | AT36: {=('1100'!A36) / 100} -> 0.334 | AU36: {=('1100'!B36) / 100} -> 0.321 | AV36: {=('1100'!C36) / 100} -> 0.327 | AW36: {=('1100'!D36) / 100} -> 0.316 | AX36: {=('1100'!E36) / 100} -> 0.338 | AY36: 23623900 | AZ36: 23621400 | BA36: 15891700 | BB36: 13209900 | BC36: 12543300 | BD36: 8746300 | BE36: 8097000 | BF36: 7752700 | BG36: 3706500 | BH36: 3839800 | BI36: 16133100 | BJ36: 15854900 | BK36: 14317200 | BL36: 7776100 | BM36: 7268300 | BN36: 5394300 | BO36: 5085100 | BP36: 4676400 | BQ36: 2455600 | BR36: 2460300
A37: Elanders AB | B37: 5560081621 | C37: SE0000119299 | D37: SWE | E37: Företagstjänster | F37: =0.083 -> 0.083 | G37: =0.075 -> 0.075 | H37: =0.071 -> 0.071 | I37: =0.083 -> 0.083 | J37: =0.083 -> 0.083 | K37: 0.085 | L37: 0.084 | M37: 0.022 | N37: 0.005 | O37: 0.018 | P37: -0.00255 | Q37: -0.00029762 | R37: 0 | S37: 0.0076779 | T37: 0.0346414 | U37: 0 | V37: 0 | W37: 0 | X37: 0 | Y37: 0 | Z37: 7203 | AA37: 2873 | AB37: 2256 | AC37: 6260 | AD37: 6696 | AE37: 1967500 | AF37: 1237130 | AG37: 1468400 | AH37: 1430800 | AI37: 660700 | AJ37: 4.0837611 | AK37: 5.9722099 | AL37: 3.7189458 | AM37: 2.3267403 | AN37: 5.5370062 | AO37: {=('1100'!G37) / 100} -> 0.0692 | AP37: {=('1100'!H37) / 100} -> 0.0607 | AQ37: {=('1100'!I37) / 100} -> 0.0516 | AR37: {=('1100'!J37) / 100} -> 0.0519 | AS37: {=('1100'!K37) / 100} -> 0.0347 | AT37: {=('1100'!A37) / 100} -> 0.245 | AU37: {=('1100'!B37) / 100} -> 0.263 | AV37: {=('1100'!C37) / 100} -> 0.278 | AW37: {=('1100'!D37) / 100} -> 0.334 | AX37: {=('1100'!E37) / 100} -> 0.302 | AY37: 13996400 | AZ37: 15171400 | BA37: 11815700 | BB37: 11118700 | BC37: 11317300 | BD37: 4452000 | BE37: 3655200 | BF37: 3304900 | BG37: 2413300 | BH37: 2480200 | BI37: 15630400 | BJ37: 14574100 | BK37: 11799600 | BL37: 8639100 | BM37: 9205400 | BN37: 3836400 | BO37: 3834800 | BP37: 3276500 | BQ37: 2887000 | BR37: 2777000
A38: Elekta AB (publ) | B38: 5561704015 | C38: SE0000163628 | D38: SWE | E38: Företagstjänster | F38: 0.097 | G38: 0.08 | H38: 0.08 | I38: 0.08 | J38: 0.08 | K38: 0.085 | L38: 0.084 | M38: 0.022 | N38: 0.005 | O38: 0.018 | P38: -0.00255 | Q38: -0.00029762 | R38: 0 | S38: 0.0076779 | T38: 0.0346414 | U38: 0 | V38: 0 | W38: 0 | X38: 0 | Y38: 0 | Z38: - | AA38: 4587 | AB38: 4631 | AC38: 4194 | AD38: 4117 | AE38: - | AF38: 2493000 | AG38: 2682000 | AH38: 3109000 | AI38: 2931000 | AJ38: - | AK38: 2.5964701 | AL38: 1.8866518 | AM38: 1.4419427 | AN38: 3.0696008 | AO38: {=('1100'!G38) / 100} -> 0.0896 | AP38: {=('1100'!H38) / 100} -> 0.0896 | AQ38: {=('1100'!I38) / 100} -> 0.117 | AR38: {=('1100'!J38) / 100} -> 0.1402 | AS38: {=('1100'!K38) / 100} -> 0.1178 | AT38: {=('1100'!A38) / 100} -> 0.329 | AU38: {=('1100'!B38) / 100} -> 0.329 | AV38: {=('1100'!C38) / 100} -> 0.339 | AW38: {=('1100'!D38) / 100} -> 0.33 | AX38: {=('1100'!E38) / 100} -> 0.286 | AY38: 18119000 | AZ38: 16869000 | BA38: 14703000 | BB38: 13860000 | BC38: 14612000 | BD38: =7849000 -> 7849000 | BE38: 6937000 | BF38: 6499000 | BG38: 5973000 | BH38: 6311000 | BI38: - | BJ38: 29608000 | BK38: 26303000 | BL38: 24844000 | BM38: 28411000 | BN38: 10774000 | BO38: 9729000 | BP38: 8912000 | BQ38: 8197000 | BR38: 8113000
A39: Enea Aktiebolag | B39: 5562097146 | C39: SE0009697220 | D39: SWE | E39: Företagstjänster | F39: =0.115 -> 0.115 | G39: =0.105 -> 0.105 | H39: =0.09 -> 0.09 | I39: =0.09 -> 0.09 | J39: =0.09 -> 0.09 | K39: 0.085 | L39: 0.084 | M39: 0.022 | N39: 0.005 | O39: 0.018 | P39: -0.00255 | Q39: -0.00029762 | R39: 0 | S39: 0.0076779 | T39: 0.0346414 | U39: =420.585*1000 -> 420585 | V39: 0 | W39: 0 | X39: 0 | Y39: 0 | Z39: 885 | AA39: 830 | AB39: 891 | AC39: 229 | AD39: 199 | AE39: 287 386 | AF39: - 3 481 646 | AG39: 60 548 | AH39: 133 557 | AI39: 50 472 | AJ39: 6.075 | AK39: - 0,608 | AL39: 32.181 | AM39: 1.305 | AN39: 10.14 | AO39: {=('1100'!G39) / 100} -> -1.68 | AP39: {=('1100'!H39) / 100} -> -1.2 | AQ39: {=('1100'!I39) / 100} -> -0.0066 | AR39: {=('1100'!J39) / 100} -> 0.0643 | AS39: {=('1100'!K39) / 100} -> -0.01 | AT39: {=('1100'!A39) / 100} -> 0.585 | AU39: {=('1100'!B39) / 100} -> 0.736 | AV39: {=('1100'!C39) / 100} -> 0.791 | AW39: {=('1100'!D39) / 100} -> 0.697 | AX39: {=('1100'!E39) / 100} -> 0.559 | AY39: 3161972 | AZ39: 3465987 | BA39: 1533240 | BB39: 1050200 | BC39: 838758 | BD39: 1726083 | BE39: 6670055 | BF39: 9280734 | BG39: 1010594 | BH39: 1053369 | BI39: 6945375 | BJ39: 12851240 | BK39: 14880340 | BL39: 2003890 | BM39: 2010770 | BN39: 4060848 | BO39: 9453619 | BP39: 11766576 | BQ39: 1396403 | BR39: 1123484
A40: Epiroc Aktiebolag | B40: 5560412149 | C40: SE0015658109 | D40: SWE | E40: Företagstjänster | F40: 0.08 | G40: 0.08 | H40: 0.08 | I40: 0.08 | J40: 0.08 | K40: 0.085 | L40: 0.084 | M40: 0.022 | N40: 0.005 | O40: 0.018 | P40: -0.00255 | Q40: -0.00029762 | R40: 0 | S40: 0.0076779 | T40: 0.0346414 | U40: 0 | V40: 0 | W40: 0 | X40: 0 | Y40: 0 | Z40: 17923 | AA40: 15969 | AB40: 14611 | AC40: 14012 | AD40: 14398 | AE40: 15846000 | AF40: 13277000 | AG40: 10740000 | AH40: 9128000 | AI40: 9947000 | AJ40: 0.82531869 | AK40: 0.70520449 | AL40: 0.92234637 | AM40: 1.2003725 | AN40: 0.84628531 | AO40: {=('1100'!G40) / 100} -> 0.2244 | AP40: {=('1100'!H40) / 100} -> 0.2291 | AQ40: {=('1100'!I40) / 100} -> 0.2311 | AR40: {=('1100'!J40) / 100} -> 0.2083 | AS40: {=('1100'!K40) / 100} -> 0.2037 | AT40: {=('1100'!A40) / 100} -> 0.543 | AU40: {=('1100'!B40) / 100} -> 0.534 | AV40: {=('1100'!C40) / 100} -> 0.531 | AW40: {=('1100'!D40) / 100} -> 0.54 | AX40: {=('1100'!E40) / 100} -> 0.555 | AY40: 60897000 | AZ40: 50042000 | BA40: 40006000 | BB40: 36287000 | BC40: 40979000 | BD40: 10222000 | BE40: 8275000 | BF40: 4089000 | BG40: 2049000 | BH40: 2185000 | BI40: 67784000 | BJ40: 61780000 | BK40: 48583000 | BL40: 43886000 | BM40: 41037000 | BN40: 36822000 | BO40: 33020000 | BP40: 25729000 | BQ40: 23693000 | BR40: 22761000
...

Sheet 1100
A1: Sol_%_23 | B1: Sol_%_22 | C1: Sol_%_21 | D1: Sol_%_20 | E1: Sol_%_19 | G1: VM_%_23 | H1: VM_%_22 | I1: VM_%_21 | J1: VM_%_20 | K1: VM_%_19
A2: 56 | B2: 44.2 | C2: 43.4 | D2: 43.5 | E2: 45.1 | G2: =9.12 -> 9.12 | H2: 5.17 | I2: 5.95 | J2: 7.83 | K2: 7.6
A3: 35.9 | B3: 33.9 | C3: 31.6 | D3: 32.8 | E3: 35.5 | G3: 12.35 | H3: 11.65 | I3: 10.72 | J3: 8.84 | K3: 9.94
A4: 44.2 | B4: 43.5 | C4: 42.4 | D4: 42.8 | E4: 38.4 | G4: 8.56 | H4: 9.43 | I4: 8.78 | J4: 9.22 | K4: 7.35
A5: 9.4 | B5: 12.9 | C5: 17.3 | D5: 18.8 | E5: 21.1 | G5: -1.9 | H5: -0.07 | I5: 5.45 | J5: 5.05 | K5: 2.74
A6: 47.1 | B6: 46.8 | C6: 43.8 | D6: 37.9 | E6: 37.7 | G6: 11.26 | H6: 8.93 | I6: 13.27 | J6: 9.54 | K6: 11.26
A7: 26.4 | B7: 25.9 | C7: 27.3 | D7: 28.4 | E7: 27 | G7: 12.57 | H7: 9.87 | I7: 11.92 | J7: 8.21 | K7: 11.54
A8: 45 | B8: 43.5 | C8: 49.9 | D8: 47.5 | E8: 42.9 | G8: 15.28 | H8: 13.03 | I8: 15.94 | J8: 14.05 | K8: 16.35
A9: 50.8 | B9: 30.6 | C9: 65.1 | D9: 62.8 | E9: 57.4 | G9: 20.63 | H9: 14.94 | I9: 12.93 | J9: 7.61 | K9: 13.56
A10: 41.1 | B10: 40.7 | C10: 39.5 | D10: 38.9 | E10: 0 | G10: 8.15 | H10: 7.31 | I10: 5.07 | J10: 4.91 | K10: 0
A11: 27.5 | B11: 26.2 | C11: 27.2 | D11: 29.4 | E11: 29.2 | G11: 7.39 | H11: 6.67 | I11: 5.22 | J11: 6.48 | K11: 4.86
A12: 62.8 | B12: 55.5 | C12: 55.7 | D12: 56.4 | E12: 52.1 | G12: 9 | H12: 7.51 | I12: 8.57 | J12: 8.66 | K12: 6.87
A13: 46.7 | B13: 55.6 | C13: 53.5 | D13: 50.1 | E13: 50.1 | G13: 15.61 | H13: 15.41 | I13: 15.02 | J13: 14.23 | K13: 15.59
A14: 50.1 | B14: 46.4 | C14: 49.5 | D14: 46.9 | E14: 47.6 | G14: 21.74 | H14: 21.62 | I14: 21.46 | J14: 19.35 | K14: 21.26
... A30: 77.1 | B30: 72 | C30: 65.8 | D30: 64.3 | E30: 54.3 | G30: 25.76 | H30: 25.63 | I30: 29.38 | J30: 24.9 | K30: 28.71
A31: 58.5 | B31: 73.6 | C31: 79.1 | D31: 69.7 | E31: 55.9 | G31: =-168 -> -168 | H31: =-120 -> -120 | I31: -0.66 | J31: 6.43 | K31: =-1 -> -1
A32: 47.7 | B32: 48.4 | C32: 47.3 | D32: 45.1 | E32: 43.4 | G32: 10.4 | H32: 7.99 | I32: 10.04 | J32: 8.17 | K32: 11.23
A33: 50.7 | B33: 46.1 | C33: 38.6 | D33: 52.1 | E33: 53.6 | G33: 14.6 | H33: 17.11 | I33: 19.24 | J33: 18.51 | K33: 23.91
A34: 48 | B34: 46 | C34: 43.1 | D34: 43.1 | E34: 47.3 | G34: 10.26 | H34: 10.28 | I34: 13.33 | J34: 11.64 | K34: 12.81
A35: 49.5 | B35: 43.8 | C35: 41.1 | D35: 44 | E35: 41 | G35: 8.85 | H35: 4.87 | I35: 3.42 | J35: 1.6 | K35: 7.39
A36: 33.4 | B36: 32.1 | C36: 32.7 | D36: 31.6 | E36: 33.8 | G36: 2.02 | H36: 3.22 | I36: 3.64 | J36: 2.95 | K36: 3.91
A37: 24.5 | B37: 26.3 | C37: 27.8 | D37: 33.4 | E37: 30.2 | G37: 6.92 | H37: 6.07 | I37: 5.16 | J37: 5.19 | K37: 3.47
A38: 32.9 | B38: 32.9 | C38: 33.9 | D38: 33 | E38: 28.6 | G38: 8.96 | H38: 8.96 | I38: 11.7 | J38: 14.02 | K38: 11.78
A39: 58.5 | B39: 73.6 | C39: 79.1 | D39: 69.7 | E39: 55.9 | G39: =-168 -> -168 | H39: =-120 -> -120 | I39: -0.66 | J39: 6.43 | K39: =-1 -> -1
A40: 54.3 | B40: 53.4 | C40: 53.1 | D40: 54 | E40: 55.5 | G40: 22.44 | H40: 22.91 | I40: 23.11 | J40: 20.83 | K40: 20.37
A41: 65.2 | B41: 66.6 | C41: 75.6 | D41: 77.8 | E41: 75.7 | G41: 13.98 | H41: 25.65 | I41: 58.85 | J41: 54.36 | K41: 30.2
A42: 34.9 | B42: 32 | C42: 34.2 | D42: 35.1 | E42: 33.3 | G42: 10.57 | H42: 6.18 | I42: 10.94 | J42: 13.87 | K42: 11.21
A43: 55.2 | B43: 51.6 | C43: 49.2 | D43: 47 | E43: 41.7 | G43: 11.12 | H43: 10.58 | I43: 10.14 | J43: 5.25 | K43: 10.62
A44: 57.5 | B44: 55.6 | C44: 46.6 | D44: 42.5 | E44: 45.8 | G44: 11.57 | H44: 14.06 | I44: 17.67 | J44: 13.37 | K44: 9.22
A45: 56.3 | B45: 57.7 | C45: 55.5 | D45: 46.7 | E45: 45.8 | G45: 12.26 | H45: 13.31 | I45: 16.2 | J45: 16.07 | K45: 8.97
A46: 52.8 | B46: 46.8 | C46: 44 | D46: 43.7 | E46: 41.2 | G46: 7.22 | H46: 4.73 | I46: 4.66 | J46: 5.43 | K46: 7.07
A47: 26.2 | B47: 27.9 | C47: 33.4 | D47: 31.3 | E47: 47.4 | G47: 6.42 | H47: 3.28 | I47: 7.77 | J47: 1.79 | K47: 7.61
A48: 58.4 | B48: 68.4 | C48: 71.1 | D48: 56.9 | E48: 53.4 | G48: 44.93 | H48: 42.52 | I48: 30.79 | J48: 20.4 | K48: 23.57
A49: 59.3 | B49: 59.7 | C49: 62 | D49: 55.4 | E49: 57.2 | G49: 22.61 | H49: 25.1 | I49: 23.38 | J49: 21.07 | K49: 23
A50: 39 | B50: 37.5 | C50: 34.8 | D50: 33.3 | E50: 38.3 | G50: 16.04 | H50: 16.49 | I50: 10.17 | J50: 8.53 | K50: 5.79
A51: 64.8 | B51: 58.5 | C51: 64.9 | D51: 60.6 | E51: 56 | G51: 16.57 | H51: 15.21 | I51: 19.41 | J51: 14.73 | K51: 13.33
... A101: 43.9 | B101: 42.4 | C101: 38.4 | D101: 42.3 | E101: 38.4 | G101: 9.4 | H101: 10.57 | I101: 14.77 | J101: 12.57 | K101: 11.21

Sheet Kopia av Blad11
A1: {=Datainsamling!AO2:AS101 / 100} -> 0.000912 | B1: 0.000517 | C1: 0.000595 | D1: 0.000783 | E1: 0.00076
A2: 0.001235 | B2: 0.001165 | C2: 0.001072 | D2: 0.000884 | E2: 0.000994
A3: 0.000856 | B3: 0.000943 | C3: 0.000878 | D3: 0.000922 | E3: 0.000735
A4: -0.00019 | B4: -7e-06 | C4: 0.000545 | D4: 0.000505 | E4: 0.000274
A5: 0.001126 | B5: 0.000893 | C5: 0.001327 | D5: 0.000954 | E5: 0.001126
A6: 0.001257 | B6: 0.000987 | C6: 0.001192 | D6: 0.000821 | E6: 0.001154
A7: 0.001528 | B7: 0.001303 | C7: 0.001594 | D7: 0.001405 | E7: 0.001635
A8: 0.002063 | B8: 0.001494 | C8: 0.001293 | D8: 0.000761 | E8: 0.001356
A9: 0.000815 | B9: 0.000731 | C9: 0.000507 | D9: 0.000491 | E9: 0
A10: 0.000739 | B10: 0.000667 | C10: 0.000522 | D10: 0.000648 | E10: 0.000486
A11: 0.0009 | B11: 0.000751 | C11: 0.000857 | D11: 0.000866 | E11: 0.000687
A12: 0.001561 | B12: 0.001541 | C12: 0.001502 | D12: 0.001423 | E12: 0.001559
A13: 0.002174 | B13: 0.002162 | C13: 0.002146 | D13: 0.001935 | E13: 0.002126
... A100: 0.00094 | B100: 0.001057 | C100: 0.001477 | D100: 0.001257 | E100: 0.001121

Sheet Projektplanering
A1: Mål | B1: Startdatum | C1: Slutdatum | D1: v, 45 | E1: v, 46 | F1: v, 47 | G1: v, 48 | H1: v, 49 | I1: v, 50 | J1: v, 51 | K1: v, 52 (ledig) | L1: v, 1 | M1: v, 2 | N1: v, 3
A2: Rårapport
A3: Information om uppsatsförfattarna
A4: Övergripande om uppsatsen
A5: Närmare uppgifter om uppsatsen innehåll
A6: Inlämning
A8: Mål
A9: Planeringsrapport
A10: Bakgrundsbeskrivning
A11: Problem och syfte
A12: Litteraturöversikt
A13: Metod för datainsamling
A14: Tänkt disposition av rapporten
... A42: Opponering utförande
A43: Utförande av seminarie | C43: 45305
A44: Mål
A45: Slutinlämning
A47: Inlämning | C47: 45310
A48: Mål
A49: Eximination

Sheet Grafer
D5: Årtal | E5: Delta WACC | F5: Delta SR
D6: 2020 | E6: -0.0008031 | F6: 0.0022524
D7: 2021 | E7: -0.0004454 | F7: 0.0002976
D8: 2022 | E8: 0.0092465 | F8: 0.0076779
D9: 2023 | E9: 0.0053222 | F9: 0.0269635

Sheet Output
A1: FÖRETAG | B1: year | C1: WACC | D1: Inflation | E1: Nedskrivning av goodwill | F1: Vinstmarginal | G1: Omsättning | H1: Goodwill | I1: Totala Tillgångar | J1: Summa Eget kapital | K1: Eget kapital / goodwill | L1: Eget kapital / Totalt kapital | M1: GWN_binary
A2: AAK AB (publ) | B2: 19 | C2: 0.114 | D2: 3 | E2: 0 | F2: 7.6 | G2: 28703000 | H2: 2114000 | I2: 22919000 | J2: 10337000 | K2: =H2/J2 -> 0.20450808 | L2: =J2/I2 -> 0.45102317 | M2: 0
A3: AAK AB (publ) | B3: 20 | C3: 0.08 | D3: 0.5 | E3: 0 | F3: 8.23 | G3: 28298000 | H3: 2103000 | I3: 22278000 | J3: 9699000 | K3: =H3/J3 -> 0.21682648 | L3: =J3/I3 -> 0.43536224 | M3: 0
A4: AAK AB (publ) | B4: 21 | C4: 0.08 | D4: 3.4 | E4: 0 | F4: 6.35 | G4: 35994000 | H4: 2270000 | I4: 27166000 | J4: 11783000 | K4: =H4/J4 -> 0.19265043 | L4: =J4/I4 -> 0.43374071 | M4: 0
A5: AAK AB (publ) | B5: 22 | C5: 0.09 | D5: 14 | E5: 0 | F5: 5.17 | G5: 50775000 | H5: 2538000 | I5: 33990000 | J5: 15036000 | K5: =H5/J5 -> 0.16879489 | L5: =J5/I5 -> 0.4423654 | M5: 0
A6: AAK AB (publ) | B6: 23 | C6: 0.1 | D6: 14.1 | E6: 0 | F6: 9.12 | G6: 46201000 | H6: 2712000 | I6: 30551000 | J6: 17117000 | K6: =H6/J6 -> 0.15843898 | L6: =J6/I6 -> 0.56027626 | M6: 0
A7: AFRY AB | B7: 19 | C7: 0.095 | D7: 3 | E7: 0 | F7: 7.35 | G7: 19823000 | H7: 11768000 | I7: 24375000 | J7: 9367000 | K7: =H7/J7 -> 1.2563254 | L7: =J7/I7 -> 0.38428718 | M7: 0
A8: AFRY AB | B8: 20 | C8: 0.09 | D8: 0.5 | E8: 0 | F8: 9.22 | G8: 19194000 | H8: 11460000 | I8: 23610000 | J8: 10096000 | K8: =H8/J8 -> 1.135103 | L8: =J8/I8 -> 0.42761542 | M8: 0
